Workbook

Sheet Dashboard
B2: Dashboard de Vendas — Porsche
B3: 100 vendas registradas · Relatório gerado automaticamente
B5: Receita Total (USD) | D5: Ticket Médio (USD) | F5: Total de Vendas | H5: Vendas Entregues
B6: =SUM('Dados Limpos'!F2:F101) -> 12827800 | D6: =AVERAGE('Dados Limpos'!F2:F101) -> 128278.01 | F6: =COUNTA('Dados Limpos'!A2:A101) -> 100 | H6: =COUNTIF('Dados Limpos'!L2:L101,"Delivered") -> 41
B9: Receita por Modelo | E9: Vendas por Forma de Pagamento
B10: Modelo | C10: Receita (USD) | E10: Forma | F10: Qtde
B11: 911 Dakar | C11: =SUMIF('Dados Limpos'!$D$2:$D$101,B11,'Dados Limpos'!$F$2:$F$101) -> 810600 | E11: Wire Transfer | F11: =COUNTIF('Dados Limpos'!$H$2:$H$101,E11) -> 26
B12: 911 Turbo S | C12: =SUMIF('Dados Limpos'!$D$2:$D$101,B12,'Dados Limpos'!$F$2:$F$101) -> 726300 | E12: Credit Card | F12: =COUNTIF('Dados Limpos'!$H$2:$H$101,E12) -> 15
B13: 911 GT3 | C13: =SUMIF('Dados Limpos'!$D$2:$D$101,B13,'Dados Limpos'!$F$2:$F$101) -> 697500 | E13: Financing | F13: =COUNTIF('Dados Limpos'!$H$2:$H$101,E13) -> 13
B14: Cayenne Turbo GT | C14: =SUMIF('Dados Limpos'!$D$2:$D$101,B14,'Dados Limpos'!$F$2:$F$101) -> 592800 | E14: Cash | F14: =COUNTIF('Dados Limpos'!$H$2:$H$101,E14) -> 12
B15: Taycan 4S | C15: =SUMIF('Dados Limpos'!$D$2:$D$101,B15,'Dados Limpos'!$F$2:$F$101) -> 514300 | E15: Bank Transfer | F15: =COUNTIF('Dados Limpos'!$H$2:$H$101,E15) -> 10
B16: Taycan Turbo | C16: =SUMIF('Dados Limpos'!$D$2:$D$101,B16,'Dados Limpos'!$F$2:$F$101) -> 475700.5 | E16: Lease | F16: =COUNTIF('Dados Limpos'!$H$2:$H$101,E16) -> 10
B17: Cayenne Coupe | C17: =SUMIF('Dados Limpos'!$D$2:$D$101,B17,'Dados Limpos'!$F$2:$F$101) -> 436250 | E17: Crypto Payment | F17: =COUNTIF('Dados Limpos'!$H$2:$H$101,E17) -> 6
B18: Taycan Turbo S | C18: =SUMIF('Dados Limpos'!$D$2:$D$101,B18,'Dados Limpos'!$F$2:$F$101) -> 432000 | E18: Debit Card | F18: =COUNTIF('Dados Limpos'!$H$2:$H$101,E18) -> 4
B19: Taycan GTS | C19: =SUMIF('Dados Limpos'!$D$2:$D$101,B19,'Dados Limpos'!$F$2:$F$101) -> 429500 | E19: ACH Payment | F19: =COUNTIF('Dados Limpos'!$H$2:$H$101,E19) -> 4
B20: Cayenne E-Hybrid | C20: =SUMIF('Dados Limpos'!$D$2:$D$101,B20,'Dados Limpos'!$F$2:$F$101) -> 373650
B21: Macan Electric | C21: =SUMIF('Dados Limpos'!$D$2:$D$101,B21,'Dados Limpos'!$F$2:$F$101) -> 360100 | E21: Vendas por Status de Entrega
B22: 718 Cayman GT4 RS | C22: =SUMIF('Dados Limpos'!$D$2:$D$101,B22,'Dados Limpos'!$F$2:$F$101) -> 350000 | E22: Status | F22: Qtde
B23: 718 Spyder RS | C23: =SUMIF('Dados Limpos'!$D$2:$D$101,B23,'Dados Limpos'!$F$2:$F$101) -> 333000 | E23: Delivered | F23: =COUNTIF('Dados Limpos'!$L$2:$L$101,E23) -> 41
B24: 911 Targa 4S | C24: =SUMIF('Dados Limpos'!$D$2:$D$101,B24,'Dados Limpos'!$F$2:$F$101) -> 315250 | E24: Pending | F24: =COUNTIF('Dados Limpos'!$L$2:$L$101,E24) -> 17
B25: Panamera | C25: =SUMIF('Dados Limpos'!$D$2:$D$101,B25,'Dados Limpos'!$F$2:$F$101) -> 304400 | E25: In Transit | F25: =COUNTIF('Dados Limpos'!$L$2:$L$101,E25) -> 15
B26: Macan T | C26: =SUMIF('Dados Limpos'!$D$2:$D$101,B26,'Dados Limpos'!$F$2:$F$101) -> 302000 | E26: Cancelled | F26: =COUNTIF('Dados Limpos'!$L$2:$L$101,E26) -> 7
B27: Cayenne S | C27: =SUMIF('Dados Limpos'!$D$2:$D$101,B27,'Dados Limpos'!$F$2:$F$101) -> 289450 | E27: Awaiting Delivery | F27: =COUNTIF('Dados Limpos'!$L$2:$L$101,E27) -> 5
B28: 911 GT3 RS | C28: =SUMIF('Dados Limpos'!$D$2:$D$101,B28,'Dados Limpos'!$F$2:$F$101) -> 286500 | E28: Pending Approval | F28: =COUNTIF('Dados Limpos'!$L$2:$L$101,E28) -> 4
B29: Macan GTS | C29: =SUMIF('Dados Limpos'!$D$2:$D$101,B29,'Dados Limpos'!$F$2:$F$101) -> 285400 | E29: Shipped | F29: =COUNTIF('Dados Limpos'!$L$2:$L$101,E29) -> 4
B30: 911 Targa 4 | C30: =SUMIF('Dados Limpos'!$D$2:$D$101,B30,'Dados Limpos'!$F$2:$F$101) -> 284500 | E30: Awaiting Pickup | F30: =COUNTIF('Dados Limpos'!$L$2:$L$101,E30) -> 4
B31: Panamera Turbo | C31: =SUMIF('Dados Limpos'!$D$2:$D$101,B31,'Dados Limpos'!$F$2:$F$101) -> 273500 | E31: Pending Review | F31: =COUNTIF('Dados Limpos'!$L$2:$L$101,E31) -> 2
B32: Panamera Turbo S | C32: =SUMIF('Dados Limpos'!$D$2:$D$101,B32,'Dados Limpos'!$F$2:$F$101) -> 266000 | E32: Awaiting Review | F32: =COUNTIF('Dados Limpos'!$L$2:$L$101,E32) -> 1
B33: 911 Carrera Cabriolet | C33: =SUMIF('Dados Limpos'!$D$2:$D$101,B33,'Dados Limpos'!$F$2:$F$101) -> 259800
B34: 911 Carrera | C34: =SUMIF('Dados Limpos'!$D$2:$D$101,B34,'Dados Limpos'!$F$2:$F$101) -> 251400
B35: Taycan Cross Turismo | C35: =SUMIF('Dados Limpos'!$D$2:$D$101,B35,'Dados Limpos'!$F$2:$F$101) -> 246400
B36: 911 Carrera GTS | C36: =SUMIF('Dados Limpos'!$D$2:$D$101,B36,'Dados Limpos'!$F$2:$F$101) -> 241650
B37: Cayenne | C37: =SUMIF('Dados Limpos'!$D$2:$D$101,B37,'Dados Limpos'!$F$2:$F$101) -> 239700
B38: Taycan | C38: =SUMIF('Dados Limpos'!$D$2:$D$101,B38,'Dados Limpos'!$F$2:$F$101) -> 236800
B39: Panamera 4S | C39: =SUMIF('Dados Limpos'!$D$2:$D$101,B39,'Dados Limpos'!$F$2:$F$101) -> 231000
B40: 718 Cayman | C40: =SUMIF('Dados Limpos'!$D$2:$D$101,B40,'Dados Limpos'!$F$2:$F$101) -> 228300
B41: 718 Boxster | C41: =SUMIF('Dados Limpos'!$D$2:$D$101,B41,'Dados Limpos'!$F$2:$F$101) -> 219400
B42: Panamera 4 E-Hybrid | C42: =SUMIF('Dados Limpos'!$D$2:$D$101,B42,'Dados Limpos'!$F$2:$F$101) -> 217750
B43: Panamera 4 | C43: =SUMIF('Dados Limpos'!$D$2:$D$101,B43,'Dados Limpos'!$F$2:$F$101) -> 205800
B44: Macan S | C44: =SUMIF('Dados Limpos'!$D$2:$D$101,B44,'Dados Limpos'!$F$2:$F$101) -> 205450
...

Sheet Dados Limpos
A1: ID Venda | B1: Data Venda | C1: Cliente | D1: Modelo Porsche | E1: Ano Modelo | F1: Preço Venda (USD) | G1: Quilometragem (mi) | H1: Forma Pagamento | I1: Cidade | J1: Estado | K1: Vendedor | L1: Status Entrega | M1: Data Inválida? | N1: Nome Incompleto?
A2: 6 | B2: INVALID | C2: Michael Adams | D2: 718 Cayman | E2: 2022 | F2: 79500 | G2: 9800 | H2: Credit Card | I2: Boston | J2: MA | K2: Kevin | L2: Delivered | M2: Sim | N2: Sim
A3: 7 | B3: 2024-03-14 | C3: Sophia Miller | D3: 911 Turbo S | E3: 2024 | F3: 235000 | G3: 1200 | H3: Wire Transfer | I3: Seattle | J3: WA | K3: Amanda Scott | L3: Delivered | M3: Não | N3: Não
A4: 8 | B4: 2024-04-18 | C4: Daniel Jones | D4: Cayenne Coupe | E4: 2023 | F4: 112750 | G4: 6400 | H4: Financing | I4: Austin | J4: TX | K4: Brian Hall | L4: In Transit | M4: Não | N4: Sim
A5: 9 | B5: INVALID | C5: Olivia Brown | D5: Macan S | E5: 2021 | F5: 68900 | G5: 28 | H5: Cash | I5: Denver | J5: CO | K5: Jessica | L5: Pending | M5: Sim | N5: Sim
A6: 10 | B6: 2024-05-22 | C6: Ethan Wilson | D6: Taycan 4S | E6: 2024 | F6: 121000 | G6: 0 | H6: Bank Transfer | I6: Los Angeles | J6: CA | K6: Thomas King | L6: Delivered | M6: Não | N6: Não
A7: 11 | B7: 2024-08-06 | C7: Ava Martinez | D7: Panamera 4 | E7: 2023 | F7: 104500 | G7: 14500 | H7: Credit Card | I7: Miami | J7: FL | K7: Lisa Ray | L7: Cancelled | M7: Não | N7: Não
A8: 12 | B8: 2024-07-11 | C8: Noah Davis | D8: 911 Carrera S | E8: 2020 | F8: 96300 | G8: 41000 | H8: Lease | I8: New York | J8: NY | K8: Mark Evans | L8: Delivered | M8: Não | N8: Não
A9: 13 | B9: INVALID | C9: Isabella Garcia | D9: Cayenne E-Hybrid | E9: 2022 | F9: 89750 | G9: 11744 | H9: Wire Transfer | I9: San Diego | J9: CA | K9: Nancy Reed | L9: Pending Approval | M9: Sim | N9: Não
A10: 14 | B10: 2024-08-19 | C10: Liam Rodriguez | D10: 718 Boxster | E10: 2021 | F10: 73500 | G10: 22300 | H10: Debit Card | I10: Chicago | J10: IL | K10: George Bell | L10: Shipped | M10: Não | N10: Não
A11: 15 | B11: 2024-09-02 | C11: Mia Hernandez | D11: Macan GTS | E11: 2024 | F11: 95000 | G11: 3500 | H11: Financing | I11: Phoenix | J11: AZ | K11: Helen Brooks | L11: In Transit | M11: Não | N11: Não
A12: 16 | B12: 2024-09-17 | C12: James Lopez | D12: Taycan Turbo | E12: 2023 | F12: 153200.5 | G12: 11 | H12: ACH Payment | I12: Dallas | J12: TX | K12: Samuel Price | L12: Delivered | M12: Não | N12: Não
A13: 17 | B13: INVALID | C13: Charlotte Young | D13: 911 GT3 | E13: 2024 | F13: 241000 | G13: 750 | H13: Wire Transfer | I13: Las Vegas | J13: NV | K13: Peter Ford | L13: Pending | M13: Sim | N13: Não
... A101: 105 | B101: 2027-10-01 | C101: Madison Powell | D101: 911 Dakar | E101: 2024 | F101: 271700 | G101: 1050 | H101: Lease | I101: New Orleans | J101: LA | K101: Steve Ross | L101: Delivered | M101: Não | N101: Não

Sheet Vendedores
B2: Ranking de Vendedores
B3: Ordenado por receita total gerada
A5: # | B5: Vendedor | C5: Nº de Vendas | D5: Receita Total (USD) | E5: Ticket Médio (USD)
A6: 1 | B6: Peter Lane | C6: =COUNTIF('Dados Limpos'!$K$2:$K$101,B6) -> 2 | D6: =SUMIF('Dados Limpos'!$K$2:$K$101,B6,'Dados Limpos'!$F$2:$F$101) -> 519000 | E6: =IFERROR(D6/C6,0) -> 259500
A7: 2 | B7: Karen Diaz | C7: =COUNTIF('Dados Limpos'!$K$2:$K$101,B7) -> 2 | D7: =SUMIF('Dados Limpos'!$K$2:$K$101,B7,'Dados Limpos'!$F$2:$F$101) -> 494000 | E7: =IFERROR(D7/C7,0) -> 247000
A8: 3 | B8: Rachel Turner | C8: =COUNTIF('Dados Limpos'!$K$2:$K$101,B8) -> 2 | D8: =SUMIF('Dados Limpos'!$K$2:$K$101,B8,'Dados Limpos'!$F$2:$F$101) -> 369800 | E8: =IFERROR(D8/C8,0) -> 184900
A9: 4 | B9: Steve Ross | C9: =COUNTIF('Dados Limpos'!$K$2:$K$101,B9) -> 2 | D9: =SUMIF('Dados Limpos'!$K$2:$K$101,B9,'Dados Limpos'!$F$2:$F$101) -> 361400 | E9: =IFERROR(D9/C9,0) -> 180700
A10: 5 | B10: Diana Long | C10: =COUNTIF('Dados Limpos'!$K$2:$K$101,B10) -> 2 | D10: =SUMIF('Dados Limpos'!$K$2:$K$101,B10,'Dados Limpos'!$F$2:$F$101) -> 351600 | E10: =IFERROR(D10/C10,0) -> 175800
A11: 6 | B11: Peter Ford | C11: =COUNTIF('Dados Limpos'!$K$2:$K$101,B11) -> 2 | D11: =SUMIF('Dados Limpos'!$K$2:$K$101,B11,'Dados Limpos'!$F$2:$F$101) -> 337800 | E11: =IFERROR(D11/C11,0) -> 168900
A12: 7 | B12: Steve Gray | C12: =COUNTIF('Dados Limpos'!$K$2:$K$101,B12) -> 2 | D12: =SUMIF('Dados Limpos'!$K$2:$K$101,B12,'Dados Limpos'!$F$2:$F$101) -> 315250 | E12: =IFERROR(D12/C12,0) -> 157625
A13: 8 | B13: Megan Reed | C13: =COUNTIF('Dados Limpos'!$K$2:$K$101,B13) -> 2 | D13: =SUMIF('Dados Limpos'!$K$2:$K$101,B13,'Dados Limpos'!$F$2:$F$101) -> 307000 | E13: =IFERROR(D13/C13,0) -> 153500
A14: 9 | B14: Patrick Wood | C14: =COUNTIF('Dados Limpos'!$K$2:$K$101,B14) -> 3 | D14: =SUMIF('Dados Limpos'!$K$2:$K$101,B14,'Dados Limpos'!$F$2:$F$101) -> 301700 | E14: =IFERROR(D14/C14,0) -> 100566.67
A15: 10 | B15: Henry King | C15: =COUNTIF('Dados Limpos'!$K$2:$K$101,B15) -> 2 | D15: =SUMIF('Dados Limpos'!$K$2:$K$101,B15,'Dados Limpos'!$F$2:$F$101) -> 293000 | E15: =IFERROR(D15/C15,0) -> 146500
A16: 11 | B16: Samuel Price | C16: =COUNTIF('Dados Limpos'!$K$2:$K$101,B16) -> 2 | D16: =SUMIF('Dados Limpos'!$K$2:$K$101,B16,'Dados Limpos'!$F$2:$F$101) -> 287200.5 | E16: =IFERROR(D16/C16,0) -> 143600.25
A17: 12 | B17: Linda Cole | C17: =COUNTIF('Dados Limpos'!$K$2:$K$101,B17) -> 2 | D17: =SUMIF('Dados Limpos'!$K$2:$K$101,B17,'Dados Limpos'!$F$2:$F$101) -> 284500 | E17: =IFERROR(D17/C17,0) -> 142250
... A75: 70 | B75: Thomas Fox | C75: =COUNTIF('Dados Limpos'!$K$2:$K$101,B75) -> 1 | D75: =SUMIF('Dados Limpos'!$K$2:$K$101,B75,'Dados Limpos'!$F$2:$F$101) -> 59000 | E75: =IFERROR(D75/C75,0) -> 59000

Sheet Qualidade dos Dados
B2: Relatório de Qualidade dos Dados
B3: Registros que precisam de revisão manual
B5: Resumo
B6: Total de registros | D6: 100
B7: Datas de venda inválidas (dia/mês inexistente) | D7: 24
B8: Nomes de cliente/vendedor incompletos ou ambíguos | D8: 7
B9: Duplicatas exatas (mesmo ID) | D9: 0
B10: Outliers de preço por modelo (>1.8 desvios-padrão) | D10: 0
B12: Datas Inválidas — Detalhe
B13: ID Venda | C13: Data Original (bruta) | D13: Cliente | E13: Modelo | F13: Problema Provável
B14: 6 | C14: 2024-02-30 | D14: Michael Adams | E14: 718 Cayman | F14: Dia ou mês fora do intervalo válido (ex: dia 30/31/32/40 ou mês 15/18)
B15: 9 | C15: April 31st, 2024 | D15: Olivia Brown | E15: Macan S | F15: Dia ou mês fora do intervalo válido (ex: dia 30/31/32/40 ou mês 15/18)
B16: 13 | C16: 2024/15/07 | D16: Isabella Garcia | E16: Cayenne E-Hybrid | F16: Dia ou mês fora do intervalo válido (ex: dia 30/31/32/40 ou mês 15/18)
B17: 17 | C17: 2024-10-40 | D17: Charlotte Young | E17: 911 GT3 | F17: Dia ou mês fora do intervalo válido (ex: dia 30/31/32/40 ou mês 15/18)
B18: 22 | C18: 01/32/2025 | D18: Henry Torres | E18: 718 Spyder RS | F18: Dia ou mês fora do intervalo válido (ex: dia 30/31/32/40 ou mês 15/18)
B19: 24 | C19: February 29th, 2025 | D19: Alexander Flores | E19: Cayenne S | F19: Dia ou mês fora do intervalo válido (ex: dia 30/31/32/40 ou mês 15/18)
B20: 28 | C20: 2025/04/31 | D20: William Roberts | E20: 911 Dakar | F20: Dia ou mês fora do intervalo válido (ex: dia 30/31/32/40 ou mês 15/18)
B21: 31 | C21: 06/31/2025 | D21: Ella Campbell | E21: 718 Cayman GT4 RS | F21: Dia ou mês fora do intervalo válido (ex: dia 30/31/32/40 ou mês 15/18)
B22: 36 | C22: 2025-09-31 | D22: Andrew Simmons | E22: 911 Carrera | F22: Dia ou mês fora do intervalo válido (ex: dia 30/31/32/40 ou mês 15/18)
B23: 43 | C23: 2025/18/11 | D23: Zoe Foster | E23: Cayenne Coupe | F23: Dia ou mês fora do intervalo válido (ex: dia 30/31/32/40 ou mês 15/18)
B24: 44 | C24: November 31st, 2025 | D24: Caleb Ward | E24: Macan GTS | F24: Dia ou mês fora do intervalo válido (ex: dia 30/31/32/40 ou mês 15/18)
B25: 47 | C25: 2025-12-40 | D25: Nora Simmons | E25: 911 GT3 RS | F25: Dia ou mês fora do intervalo válido (ex: dia 30/31/32/40 ou mês 15/18)
... B37: 102 | C37: August 32nd, 2027 | D37: Hunter Griffin | E37: 911 Targa 4 | F37: Dia ou mês fora do intervalo válido (ex: dia 30/31/32/40 ou mês 15/18)
B39: Nomes Incompletos/Ambíguos — Detalhe
B40: ID Venda | C40: Cliente (bruto) | D40: Vendedor (bruto) | E40: Observação
B41: 6 | C41: Michael Adams | D41: kevin | E41: Vendedor com apenas um nome — sobrenome ausente
B42: 8 | C42: Daniel-Jones | D42: Brian Hall | E42: Nome do cliente com hífen — provável nome/sobrenome faltando
B43: 9 | C43: Olivia Brown | D43: jessica | E43: Vendedor com apenas um nome — sobrenome ausente
B44: 36 | C44: Andrew Simmons | D44: natalie | E44: Vendedor com apenas um nome — sobrenome ausente
B45: 38 | C45: Ryan-Cooper | D45: Patricia Fox | E45: Nome do cliente com hífen — provável nome/sobrenome faltando
B46: 42 | C46: Nathan Hughes | D46: monica | E46: Vendedor com apenas um nome — sobrenome ausente
B47: 88 | C47: Tyler-Morris | D47: Brian Hall | E47: Nome do cliente com hífen — provável nome/sobrenome faltando
